<sdf version='1.10'>
  <world name='ackermann_steering'>
    <physics name='1ms' type='ignored'>
      <max_step_size>0.001</max_step_size>
      <real_time_factor>1</real_time_factor>
      <real_time_update_rate>1000</real_time_update_rate>
    </physics>
    <plugin name='gz::sim::systems::Physics' filename='gz-sim-physics-system'/>
    <plugin name='gz::sim::systems::UserCommands' filename='gz-sim-user-commands-system'/>
    <plugin name='gz::sim::systems::SceneBroadcaster' filename='gz-sim-scene-broadcaster-system'/>
    <gravity>0 0 -9.8000000000000007</gravity>
    <magnetic_field>5.5644999999999998e-06 2.2875799999999999e-05 -4.2388400000000002e-05</magnetic_field>
    <atmosphere type='adiabatic'/>
    <scene>
      <ambient>0.400000006 0.400000006 0.400000006 1</ambient>
      <background>0.699999988 0.699999988 0.699999988 1</background>
      <shadows>true</shadows>
    </scene>
    <model name='ground_plane'>
      <static>true</static>
      <link name='link'>
        <collision name='collision'>
          <geometry>
            <plane>
              <normal>0 0 1</normal>
              <size>100 100</size>
            </plane>
          </geometry>
          <surface>
            <friction>
              <ode>
                <mu>50</mu>
              </ode>
              <bullet>
                <friction>1</friction>
                <rolling_friction>0.10000000000000001</rolling_friction>
              </bullet>
            </friction>
            <bounce/>
            <contact/>
          </surface>
        </collision>
        <visual name='visual'>
          <geometry>
            <plane>
              <normal>0 0 1</normal>
              <size>100 100</size>
            </plane>
          </geometry>
          <material>
            <ambient>0.800000012 0.800000012 0.800000012 1</ambient>
            <diffuse>0.800000012 0.800000012 0.800000012 1</diffuse>
            <specular>0.800000012 0.800000012 0.800000012 1</specular>
          </material>
        </visual>
        <pose>0 0 0 0 0 0</pose>
        <inertial>
          <pose>0 0 0 0 0 0</pose>
          <mass>1</mass>
          <inertia>
            <ixx>1</ixx>
            <ixy>0</ixy>
            <ixz>0</ixz>
            <iyy>1</iyy>
            <iyz>0</iyz>
            <izz>1</izz>
          </inertia>
        </inertial>
        <enable_wind>false</enable_wind>
      </link>
      <pose>0 0 0 0 0 0</pose>
      <self_collide>false</self_collide>
    </model>
    <model name='vehicle_blue'>
      <pose>8.7566537354533125e-11 2.0000000001634253 0.3250071890159123 -5.0518222677781699e-10 3.1007408737803522e-10 -5.1850145662276096e-12</pose>
      <link name='chassis'>
        <pose>-0.15142700000000001 0 0.17499999999999999 0 0 0</pose>
        <inertial>
          <mass>1.14395</mass>
          <inertia>
            <ixx>0.126164</ixx>
            <ixy>0</ixy>
            <ixz>0</ixz>
            <iyy>0.41651899999999997</iyy>
            <iyz>0</iyz>
            <izz>0.481014</izz>
          </inertia>
          <pose>0 0 0 0 0 0</pose>
        </inertial>
        <visual name='visual'>
          <geometry>
            <box>
              <size>2.0114200000000002 1 0.56872599999999995</size>
            </box>
          </geometry>
          <material>
            <ambient>0.5 0.5 1 1</ambient>
            <diffuse>0.5 0.5 1 1</diffuse>
            <specular>0 0 1 1</specular>
          </material>
        </visual>
        <collision name='collision'>
          <geometry>
            <box>
              <size>2.0114200000000002 1 0.56872599999999995</size>
            </box>
          </geometry>
          <surface>
            <friction>
              <ode/>
            </friction>
            <bounce/>
            <contact/>
          </surface>
        </collision>
        <enable_wind>false</enable_wind>
      </link>
      <link name='front_left_wheel'>
        <pose>0.55428299994665509 0.6250290000000005 -0.025000000000000022 -1.5706999999999995 -9.145556648555931e-15 4.2666024538867574e-10</pose>
        <inertial>
          <mass>2</mass>
          <inertia>
            <ixx>0.14583299999999999</ixx>
            <ixy>0</ixy>
            <ixz>0</ixz>
            <iyy>0.14583299999999999</iyy>
            <iyz>0</iyz>
            <izz>0.125</izz>
          </inertia>
          <pose>0 0 0 0 0 0</pose>
        </inertial>
        <visual name='visual'>
          <geometry>
            <cylinder>
              <length>0.14999999999999999</length>
              <radius>0.29999999999999999</radius>
            </cylinder>
          </geometry>
          <material>
            <ambient>0.200000003 0.200000003 0.200000003 1</ambient>
            <diffuse>0.200000003 0.200000003 0.200000003 1</diffuse>
            <specular>0.200000003 0.200000003 0.200000003 1</specular>
          </material>
        </visual>
        <collision name='collision'>
          <geometry>
            <cylinder>
              <length>0.14999999999999999</length>
              <radius>0.29999999999999999</radius>
            </cylinder>
          </geometry>
          <surface>
            <friction>
              <ode>
                <mu>0.5</mu>
                <mu2>1</mu2>
                <fdir1>0 0 1</fdir1>
              </ode>
              <bullet>
                <friction>0.5</friction>
                <friction2>1</friction2>
                <rolling_friction>0.10000000000000001</rolling_friction>
              </bullet>
            </friction>
            <bounce/>
            <contact/>
          </surface>
        </collision>
        <enable_wind>false</enable_wind>
      </link>
      <link name='rear_left_wheel'>
        <pose>-0.95713800000000027 0.62502900000000006 -0.025000000000000022 -1.5706999999999995 -2.9522270427279027e-15 -2.8437852876896552e-19</pose>
        <inertial>
          <mass>2</mass>
          <inertia>
            <ixx>0.14583299999999999</ixx>
            <ixy>0</ixy>
            <ixz>0</ixz>
            <iyy>0.14583299999999999</iyy>
            <iyz>0</iyz>
            <izz>0.125</izz>
          </inertia>
          <pose>0 0 0 0 0 0</pose>
        </inertial>
        <visual name='visual'>
          <geometry>
            <cylinder>
              <length>0.14999999999999999</length>
              <radius>0.29999999999999999</radius>
            </cylinder>
          </geometry>
          <material>
            <ambient>0.200000003 0.200000003 0.200000003 1</ambient>
            <diffuse>0.200000003 0.200000003 0.200000003 1</diffuse>
            <specular>0.200000003 0.200000003 0.200000003 1</specular>
          </material>
        </visual>
        <collision name='collision'>
          <geometry>
            <cylinder>
              <length>0.14999999999999999</length>
              <radius>0.29999999999999999</radius>
            </cylinder>
          </geometry>
          <surface>
            <friction>
              <ode>
                <mu>0.5</mu>
                <mu2>1</mu2>
                <fdir1>0 0 1</fdir1>
              </ode>
              <bullet>
                <friction>0.5</friction>
                <friction2>1</friction2>
                <rolling_friction>0.5</rolling_friction>
              </bullet>
            </friction>
            <bounce/>
            <contact/>
          </surface>
        </collision>
        <enable_wind>false</enable_wind>
      </link>
      <link name='front_right_wheel'>
        <pose>0.55428200005334449 -0.62502900000000028 -0.024999999999999967 -1.5706999999999995 1.6772747307446438e-14 4.2665521801114974e-10</pose>
        <inertial>
          <mass>2</mass>
          <inertia>
            <ixx>0.14583299999999999</ixx>
            <ixy>0</ixy>
            <ixz>0</ixz>
            <iyy>0.14583299999999999</iyy>
            <iyz>0</iyz>
            <izz>0.125</izz>
          </inertia>
          <pose>0 0 0 0 0 0</pose>
        </inertial>
        <visual name='visual'>
          <geometry>
            <cylinder>
              <length>0.14999999999999999</length>
              <radius>0.29999999999999999</radius>
            </cylinder>
          </geometry>
          <material>
            <ambient>0.200000003 0.200000003 0.200000003 1</ambient>
            <diffuse>0.200000003 0.200000003 0.200000003 1</diffuse>
            <specular>0.200000003 0.200000003 0.200000003 1</specular>
          </material>
        </visual>
        <collision name='collision'>
          <geometry>
            <cylinder>
              <length>0.14999999999999999</length>
              <radius>0.29999999999999999</radius>
            </cylinder>
          </geometry>
          <surface>
            <friction>
              <ode>
                <mu>0.5</mu>
                <mu2>1</mu2>
                <fdir1>0 0 1</fdir1>
              </ode>
              <bullet>
                <friction>0.5</friction>
                <friction2>1</friction2>
                <rolling_friction>0.10000000000000001</rolling_friction>
              </bullet>
            </friction>
            <bounce/>
            <contact/>
          </surface>
        </collision>
        <enable_wind>false</enable_wind>
      </link>
      <link name='rear_right_wheel'>
        <pose>-0.95713800000000004 -0.62502899999999983 -0.025000000000000022 -1.5706999999999995 -4.6792353216849343e-15 -4.507357451652125e-19</pose>
        <inertial>
          <mass>2</mass>
          <inertia>
            <ixx>0.14583299999999999</ixx>
            <ixy>0</ixy>
            <ixz>0</ixz>
            <iyy>0.14583299999999999</iyy>
            <iyz>0</iyz>
            <izz>0.125</izz>
          </inertia>
          <pose>0 0 0 0 0 0</pose>
        </inertial>
        <visual name='visual'>
          <geometry>
            <cylinder>
              <length>0.14999999999999999</length>
              <radius>0.29999999999999999</radius>
            </cylinder>
          </geometry>
          <material>
            <ambient>0.200000003 0.200000003 0.200000003 1</ambient>
            <diffuse>0.200000003 0.200000003 0.200000003 1</diffuse>
            <specular>0.200000003 0.200000003 0.200000003 1</specular>
          </material>
        </visual>
        <collision name='collision'>
          <geometry>
            <cylinder>
              <length>0.14999999999999999</length>
              <radius>0.29999999999999999</radius>
            </cylinder>
          </geometry>
          <surface>
            <friction>
              <ode>
                <mu>0.5</mu>
                <mu2>1</mu2>
                <fdir1>0 0 1</fdir1>
              </ode>
              <bullet>
                <friction>0.5</friction>
                <friction2>1</friction2>
                <rolling_friction>0.5</rolling_friction>
              </bullet>
            </friction>
            <bounce/>
            <contact/>
          </surface>
        </collision>
        <enable_wind>false</enable_wind>
      </link>
      <link name='front_left_wheel_steering_link'>
        <pose>0.55428300000000008 0.5 0.019999999999999962 4.2777962009110771e-26 4.852013700537918e-26 4.2666024626963793e-10</pose>
        <inertial>
          <mass>0.5</mass>
          <inertia>
            <ixx>0.015299999999999999</ixx>
            <iyy>0.025000000000000001</iyy>
            <izz>0.015299999999999999</izz>
            <ixy>0</ixy>
            <ixz>0</ixz>
            <iyz>0</iyz>
          </inertia>
          <pose>0 0 0 0 0 0</pose>
        </inertial>
        <visual name='steering_link_visual'>
          <pose>0 0 0 0 0 0</pose>
          <geometry>
            <cylinder>
              <length>0.10000000000000001</length>
              <radius>0.029999999999999999</radius>
            </cylinder>
          </geometry>
          <material>
            <ambient>1 1 1 1</ambient>
            <diffuse>1 1 1 1</diffuse>
          </material>
        </visual>
        <enable_wind>false</enable_wind>
      </link>
      <link name='front_right_wheel_steering_link'>
        <pose>0.55428300000000008 -0.5 0.019999999999999962 -4.5858317481205403e-27 -5.4877439555714035e-26 4.2665521639548491e-10</pose>
        <inertial>
          <mass>0.5</mass>
          <inertia>
            <ixx>0.015299999999999999</ixx>
            <iyy>0.025000000000000001</iyy>
            <izz>0.015299999999999999</izz>
            <ixy>0</ixy>
            <ixz>0</ixz>
            <iyz>0</iyz>
          </inertia>
          <pose>0 0 0 0 0 0</pose>
        </inertial>
        <visual name='steering_link_visual'>
          <pose>0 0 0 0 0 0</pose>
          <geometry>
            <cylinder>
              <length>0.10000000000000001</length>
              <radius>0.029999999999999999</radius>
            </cylinder>
          </geometry>
          <material>
            <ambient>1 1 1 1</ambient>
            <diffuse>1 1 1 1</diffuse>
          </material>
        </visual>
        <enable_wind>false</enable_wind>
      </link>
      <joint name='front_left_wheel_steering_joint' type='revolute'>
        <child>front_left_wheel_steering_link</child>
        <parent>chassis</parent>
        <axis>
          <xyz>0 0 1</xyz>
          <limit>
            <lower>-0.59999999999999998</lower>
            <upper>0.59999999999999998</upper>
            <effort>25</effort>
            <velocity>1</velocity>
            <stiffness>100000000</stiffness>
            <dissipation>1</dissipation>
          </limit>
          <dynamics>
            <spring_reference>0</spring_reference>
            <spring_stiffness>0</spring_stiffness>
            <damping>0</damping>
            <friction>0</friction>
          </dynamics>
        </axis>
        <pose>0 0 0 0 0 0</pose>
      </joint>
      <joint name='front_right_wheel_steering_joint' type='revolute'>
        <parent>chassis</parent>
        <child>front_right_wheel_steering_link</child>
        <axis>
          <xyz>0 0 1</xyz>
          <limit>
            <lower>-0.59999999999999998</lower>
            <upper>0.59999999999999998</upper>
            <effort>25</effort>
            <velocity>1</velocity>
            <stiffness>100000000</stiffness>
            <dissipation>1</dissipation>
          </limit>
          <dynamics>
            <spring_reference>0</spring_reference>
            <spring_stiffness>0</spring_stiffness>
            <damping>0</damping>
            <friction>0</friction>
          </dynamics>
        </axis>
        <pose>0 0 0 0 0 0</pose>
      </joint>
      <joint name='front_left_wheel_joint' type='revolute'>
        <parent>front_left_wheel_steering_link</parent>
        <child>front_left_wheel</child>
        <axis>
          <xyz>0 0 1</xyz>
          <limit>
            <lower>-1.7976900000000001e+308</lower>
            <upper>1.7976900000000001e+308</upper>
            <effort>inf</effort>
            <velocity>inf</velocity>
            <stiffness>100000000</stiffness>
            <dissipation>1</dissipation>
          </limit>
          <dynamics>
            <spring_reference>0</spring_reference>
            <spring_stiffness>0</spring_stiffness>
            <damping>0</damping>
            <friction>0</friction>
          </dynamics>
        </axis>
        <pose>0 0 1.11022e-16 0 0 0</pose>
      </joint>
      <joint name='front_right_wheel_joint' type='revolute'>
        <parent>front_right_wheel_steering_link</parent>
        <child>front_right_wheel</child>
        <axis>
          <xyz>0 0 1</xyz>
          <limit>
            <lower>-1.7976900000000001e+308</lower>
            <upper>1.7976900000000001e+308</upper>
            <effort>inf</effort>
            <velocity>inf</velocity>
            <stiffness>100000000</stiffness>
            <dissipation>1</dissipation>
          </limit>
          <dynamics>
            <spring_reference>0</spring_reference>
            <spring_stiffness>0</spring_stiffness>
            <damping>0</damping>
            <friction>0</friction>
          </dynamics>
        </axis>
        <pose>-1.11022e-16 0 0 0 0 0</pose>
      </joint>
      <joint name='rear_left_wheel_joint' type='revolute'>
        <parent>chassis</parent>
        <child>rear_left_wheel</child>
        <axis>
          <xyz>0 0 1</xyz>
          <limit>
            <lower>-1.7976900000000001e+308</lower>
            <upper>1.7976900000000001e+308</upper>
            <effort>inf</effort>
            <velocity>inf</velocity>
            <stiffness>100000000</stiffness>
            <dissipation>1</dissipation>
          </limit>
          <dynamics>
            <spring_reference>0</spring_reference>
            <spring_stiffness>0</spring_stiffness>
            <damping>0</damping>
            <friction>0</friction>
          </dynamics>
        </axis>
        <pose>0 0 1.11022e-16 0 0 0</pose>
      </joint>
      <joint name='rear_right_wheel_joint' type='revolute'>
        <parent>chassis</parent>
        <child>rear_right_wheel</child>
        <axis>
          <xyz>0 0 1</xyz>
          <limit>
            <lower>-1.7976900000000001e+308</lower>
            <upper>1.7976900000000001e+308</upper>
            <effort>inf</effort>
            <velocity>inf</velocity>
            <stiffness>100000000</stiffness>
            <dissipation>1</dissipation>
          </limit>
          <dynamics>
            <spring_reference>0</spring_reference>
            <spring_stiffness>0</spring_stiffness>
            <damping>0</damping>
            <friction>0</friction>
          </dynamics>
        </axis>
        <pose>0 0 0 0 0 0</pose>
      </joint>
      <plugin name='gz::sim::systems::AckermannSteering' filename='gz-sim-ackermann-steering-system'>
        <left_joint>front_left_wheel_joint</left_joint>
        <left_joint>rear_left_wheel_joint</left_joint>
        <right_joint>front_right_wheel_joint</right_joint>
        <right_joint>rear_right_wheel_joint</right_joint>
        <left_steering_joint>front_left_wheel_steering_joint</left_steering_joint>
        <right_steering_joint>front_right_wheel_steering_joint</right_steering_joint>
        <kingpin_width>1.0</kingpin_width>
        <steering_limit>0.5</steering_limit>
        <wheel_base>1.0</wheel_base>
        <wheel_separation>1.25</wheel_separation>
        <wheel_radius>0.3</wheel_radius>
        <min_velocity>-1</min_velocity>
        <max_velocity>1</max_velocity>
        <min_acceleration>-3</min_acceleration>
        <max_acceleration>3</max_acceleration>
      </plugin>
      <static>false</static>
      <self_collide>false</self_collide>
    </model>
    <light name='sun' type='directional'>
      <pose>0 0 10 0 0 0</pose>
      <cast_shadows>true</cast_shadows>
      <intensity>1</intensity>
      <direction>-0.5 0.10000000000000001 -0.90000000000000002</direction>
      <diffuse>1 1 1 1</diffuse>
      <specular>0.5 0.5 0.5 1</specular>
      <attenuation>
        <range>1000</range>
        <linear>0.0099999997764825821</linear>
        <constant>0.89999997615814209</constant>
        <quadratic>0.0010000000474974513</quadratic>
      </attenuation>
      <spot>
        <inner_angle>0</inner_angle>
        <outer_angle>0</outer_angle>
        <falloff>0</falloff>
      </spot>
    </light>
  </world>
</sdf>
